Workbook

Sheet Summary
A1: Yrdly Web App - QA Checklist
A2: Go to the Checklist tab, set Status per row (dropdown), add your name, date and any bug link. This page updates itself.
A4: How to use
A5: Status: Not started / Pass / Fail / Blocked. Pass only if the expected result happened exactly. Anything else is Fail.
A6: Priority: P0 = money, auth, security (must pass). P1 = core features. P2 = polish.
A7: Every Fail needs a bug link or note. Every Pass needs a tester name and date.
A8: Money tests: always reconcile against the Payluk / Paystack dashboard and the bank, not just the app screen.
A9: Example row: ID MB-01 | Status Pass | Tester Ada | Date 2026-10-06 | Notes: Paid NGN 5,000, fee NGN 150 matched Payluk dashboard.
A10: Items marked '(if built)' that don't exist yet should be marked Fail and noted as a gap.
A13: Overall
A14: Total tests | B14: =COUNTA(Checklist!$F$2:$F$196) -> 195
A15: Pass | B15: =COUNTIF(Checklist!$F$2:$F$196,"Pass") -> 70
A16: Fail | B16: =COUNTIF(Checklist!$F$2:$F$196,"Fail") -> 4
A17: Blocked | B17: =COUNTIF(Checklist!$F$2:$F$196,"Blocked") -> 7
A18: Not started | B18: =COUNTIF(Checklist!$F$2:$F$196,"Not started") -> 114
A19: % passed | B19: =IF(B14=0,0,B15/B14) -> 0.35897436
A20: P0 total | B20: =COUNTIF(Checklist!$C$2:$C$196,"P0") -> 94
A21: P0 passed | B21: =COUNTIFS(Checklist!$C$2:$C$196,"P0",Checklist!$F$2:$F$196,"Pass") -> 37
A22: P0 failed/blocked | B22: =COUNTIFS(Checklist!$C$2:$C$196,"P0",Checklist!$F$2:$F$196,"Fail")+COUNTIFS(Checklist!$C$2:$C$196,"P0",Checklist!$F$2:$F$196,"Blocked") -> 9
A23: P0 not started | B23: =COUNTIFS(Checklist!$C$2:$C$196,"P0",Checklist!$F$2:$F$196,"Not started") -> 48
A25: P0 launch gate | B25: =IF(B20=B21,"CLEAR","NOT CLEAR") -> NOT CLEAR
A27: By area | B27: Total | C27: Pass | D27: Fail | E27: Blocked | F27: Not started | G27: % passed
A28: Auth | B28: =COUNTIF(Checklist!$B$2:$B$196,$A28) -> 12 | C28: =COUNTIFS(Checklist!$B$2:$B$196,$A28,Checklist!$F$2:$F$196,"Pass") -> 12 | D28: =COUNTIFS(Checklist!$B$2:$B$196,$A28,Checklist!$F$2:$F$196,"Fail") -> 0 | E28: =COUNTIFS(Checklist!$B$2:$B$196,$A28,Checklist!$F$2:$F$196,"Blocked") -> 0 | F28: =COUNTIFS(Checklist!$B$2:$B$196,$A28,Checklist!$F$2:$F$196,"Not started") -> 0 | G28: =IF(B28=0,0,C28/B28) -> 1
A29: Profile & Settings | B29: =COUNTIF(Checklist!$B$2:$B$196,$A29) -> 6 | C29: =COUNTIFS(Checklist!$B$2:$B$196,$A29,Checklist!$F$2:$F$196,"Pass") -> 4 | D29: =COUNTIFS(Checklist!$B$2:$B$196,$A29,Checklist!$F$2:$F$196,"Fail") -> 0 | E29: =COUNTIFS(Checklist!$B$2:$B$196,$A29,Checklist!$F$2:$F$196,"Blocked") -> 0 | F29: =COUNTIFS(Checklist!$B$2:$B$196,$A29,Checklist!$F$2:$F$196,"Not started") -> 2 | G29: =IF(B29=0,0,C29/B29) -> 0.66666667
A30: Identity Verification (NIN) | B30: =COUNTIF(Checklist!$B$2:$B$196,$A30) -> 7 | C30: =COUNTIFS(Checklist!$B$2:$B$196,$A30,Checklist!$F$2:$F$196,"Pass") -> 0 | D30: =COUNTIFS(Checklist!$B$2:$B$196,$A30,Checklist!$F$2:$F$196,"Fail") -> 0 | E30: =COUNTIFS(Checklist!$B$2:$B$196,$A30,Checklist!$F$2:$F$196,"Blocked") -> 0 | F30: =COUNTIFS(Checklist!$B$2:$B$196,$A30,Checklist!$F$2:$F$196,"Not started") -> 7 | G30: =IF(B30=0,0,C30/B30) -> 0
A31: Posts & Feed | B31: =COUNTIF(Checklist!$B$2:$B$196,$A31) -> 14 | C31: =COUNTIFS(Checklist!$B$2:$B$196,$A31,Checklist!$F$2:$F$196,"Pass") -> 10 | D31: =COUNTIFS(Checklist!$B$2:$B$196,$A31,Checklist!$F$2:$F$196,"Fail") -> 2 | E31: =COUNTIFS(Checklist!$B$2:$B$196,$A31,Checklist!$F$2:$F$196,"Blocked") -> 0 | F31: =COUNTIFS(Checklist!$B$2:$B$196,$A31,Checklist!$F$2:$F$196,"Not started") -> 2 | G31: =IF(B31=0,0,C31/B31) -> 0.71428571
A32: Friend Requests | B32: =COUNTIF(Checklist!$B$2:$B$196,$A32) -> 10 | C32: =COUNTIFS(Checklist!$B$2:$B$196,$A32,Checklist!$F$2:$F$196,"Pass") -> 2 | D32: =COUNTIFS(Checklist!$B$2:$B$196,$A32,Checklist!$F$2:$F$196,"Fail") -> 0 | E32: =COUNTIFS(Checklist!$B$2:$B$196,$A32,Checklist!$F$2:$F$196,"Blocked") -> 2 | F32: =COUNTIFS(Checklist!$B$2:$B$196,$A32,Checklist!$F$2:$F$196,"Not started") -> 6 | G32: =IF(B32=0,0,C32/B32) -> 0.2
A33: Chat | B33: =COUNTIF(Checklist!$B$2:$B$196,$A33) -> 7 | C33: =COUNTIFS(Checklist!$B$2:$B$196,$A33,Checklist!$F$2:$F$196,"Pass") -> 2 | D33: =COUNTIFS(Checklist!$B$2:$B$196,$A33,Checklist!$F$2:$F$196,"Fail") -> 0 | E33: =COUNTIFS(Checklist!$B$2:$B$196,$A33,Checklist!$F$2:$F$196,"Blocked") -> 0 | F33: =COUNTIFS(Checklist!$B$2:$B$196,$A33,Checklist!$F$2:$F$196,"Not started") -> 5 | G33: =IF(B33=0,0,C33/B33) -> 0.28571429
A34: Marketplace Listings | B34: =COUNTIF(Checklist!$B$2:$B$196,$A34) -> 7 | C34: =COUNTIFS(Checklist!$B$2:$B$196,$A34,Checklist!$F$2:$F$196,"Pass") -> 3 | D34: =COUNTIFS(Checklist!$B$2:$B$196,$A34,Checklist!$F$2:$F$196,"Fail") -> 0 | E34: =COUNTIFS(Checklist!$B$2:$B$196,$A34,Checklist!$F$2:$F$196,"Blocked") -> 0 | F34: =COUNTIFS(Checklist!$B$2:$B$196,$A34,Checklist!$F$2:$F$196,"Not started") -> 4 | G34: =IF(B34=0,0,C34/B34) -> 0.42857143
A35: Marketplace Buying & Escrow | B35: =COUNTIF(Checklist!$B$2:$B$196,$A35) -> 11 | C35: =COUNTIFS(Checklist!$B$2:$B$196,$A35,Checklist!$F$2:$F$196,"Pass") -> 6 | D35: =COUNTIFS(Checklist!$B$2:$B$196,$A35,Checklist!$F$2:$F$196,"Fail") -> 0 | E35: =COUNTIFS(Checklist!$B$2:$B$196,$A35,Checklist!$F$2:$F$196,"Blocked") -> 1 | F35: =COUNTIFS(Checklist!$B$2:$B$196,$A35,Checklist!$F$2:$F$196,"Not started") -> 4 | G35: =IF(B35=0,0,C35/B35) -> 0.54545455
A36: Marketplace Refunds & Disputes | B36: =COUNTIF(Checklist!$B$2:$B$196,$A36) -> 11 | C36: =COUNTIFS(Checklist!$B$2:$B$196,$A36,Checklist!$F$2:$F$196,"Pass") -> 0 | D36: =COUNTIFS(Checklist!$B$2:$B$196,$A36,Checklist!$F$2:$F$196,"Fail") -> 0 | E36: =COUNTIFS(Checklist!$B$2:$B$196,$A36,Checklist!$F$2:$F$196,"Blocked") -> 0 | F36: =COUNTIFS(Checklist!$B$2:$B$196,$A36,Checklist!$F$2:$F$196,"Not started") -> 11 | G36: =IF(B36=0,0,C36/B36) -> 0
A37: Seller Payouts & Withdrawals | B37: =COUNTIF(Checklist!$B$2:$B$196,$A37) -> 11 | C37: =COUNTIFS(Checklist!$B$2:$B$196,$A37,Checklist!$F$2:$F$196,"Pass") -> 8 | D37: =COUNTIFS(Checklist!$B$2:$B$196,$A37,Checklist!$F$2:$F$196,"Fail") -> 0 | E37: =COUNTIFS(Checklist!$B$2:$B$196,$A37,Checklist!$F$2:$F$196,"Blocked") -> 1 | F37: =COUNTIFS(Checklist!$B$2:$B$196,$A37,Checklist!$F$2:$F$196,"Not started") -> 2 | G37: =IF(B37=0,0,C37/B37) -> 0.72727273
A38: Events | B38: =COUNTIF(Checklist!$B$2:$B$196,$A38) -> 9 | C38: =COUNTIFS(Checklist!$B$2:$B$196,$A38,Checklist!$F$2:$F$196,"Pass") -> 2 | D38: =COUNTIFS(Checklist!$B$2:$B$196,$A38,Checklist!$F$2:$F$196,"Fail") -> 0 | E38: =COUNTIFS(Checklist!$B$2:$B$196,$A38,Checklist!$F$2:$F$196,"Blocked") -> 0 | F38: =COUNTIFS(Checklist!$B$2:$B$196,$A38,Checklist!$F$2:$F$196,"Not started") -> 7 | G38: =IF(B38=0,0,C38/B38) -> 0.22222222
A39: Ticket Purchase (Paystack) | B39: =COUNTIF(Checklist!$B$2:$B$196,$A39) -> 7 | C39: =COUNTIFS(Checklist!$B$2:$B$196,$A39,Checklist!$F$2:$F$196,"Pass") -> 1 | D39: =COUNTIFS(Checklist!$B$2:$B$196,$A39,Checklist!$F$2:$F$196,"Fail") -> 1 | E39: =COUNTIFS(Checklist!$B$2:$B$196,$A39,Checklist!$F$2:$F$196,"Blocked") -> 0 | F39: =COUNTIFS(Checklist!$B$2:$B$196,$A39,Checklist!$F$2:$F$196,"Not started") -> 5 | G39: =IF(B39=0,0,C39/B39) -> 0.14285714
... A51: Marketing Site & Email | B51: =COUNTIF(Checklist!$B$2:$B$196,$A51) -> 4 | C51: =COUNTIFS(Checklist!$B$2:$B$196,$A51,Checklist!$F$2:$F$196,"Pass") -> 4 | D51: =COUNTIFS(Checklist!$B$2:$B$196,$A51,Checklist!$F$2:$F$196,"Fail") -> 0 | E51: =COUNTIFS(Checklist!$B$2:$B$196,$A51,Checklist!$F$2:$F$196,"Blocked") -> 0 | F51: =COUNTIFS(Checklist!$B$2:$B$196,$A51,Checklist!$F$2:$F$196,"Not started") -> 0 | G51: =IF(B51=0,0,C51/B51) -> 1

Sheet Checklist
A1: ID | B1: Area | C1: Priority | D1: Test case | E1: Expected result | F1: Status | G1: Tester | H1: Date tested | I1: Bug link / notes
A2: AU-04 | B2: Auth | C2: P0 | D2: Phone OTP (Termii): correct code, wrong code, expired code, resend spam | E2: Correct verifies; wrong/expired rejected; resend is throttled | F2: Pass | G2: Caleb | H2: 46152 | I2: No place to input phone number after signup, and if you use signup with google it does not show you to input your phone number during onboarding
A3: AU-05 | B3: Auth | C3: P0 | D3: Login: right password, wrong password, unverified account | E3: Right logs in; wrong gives error; unverified is handled clearly | F3: Pass | G3: Caleb | H3: 46152
A4: AU-06 | B4: Auth | C4: P0 | D4: Google sign-in (new user and existing user) | E4: Works for both; consent screen shows Yrdly / api.yrdly.ng branding | F4: Pass | G4: Caleb | H4: 46152
A5: AU-07 | B5: Auth | C5: P0 | D5: Forgot password full flow | E5: Email arrives; reset works; old password no longer works | F5: Pass | G5: Caleb | H5: 46152
A6: AU-10 | B6: Auth | C6: P0 | D6: Open protected routes while logged out | E6: Redirects to login, then returns to intended page | F6: Pass | G6: Caleb | H6: 46152 | I6: When visiting a protected route it takes you to login if you are not signed in but when you do sign in it takes you to the home feed instead of the intended page
A7: PO-04 | B7: Posts & Feed | C7: P0 | D7: Like a post | E7: Count +1, heart filled, persists after refresh | F7: Pass | G7: Caleb | H7: 46152
A8: PO-05 | B8: Posts & Feed | C8: P0 | D8: Unlike a post | E8: Count -1, heart empty, persists after refresh | F8: Pass | G8: Caleb | H8: 46152
A9: PO-06 | B9: Posts & Feed | C9: P0 | D9: Rapid double-click / spam like | E9: Never double counts; final state matches server | F9: Pass | G9: Caleb | H9: 46152
A10: FR-01 | B10: Friend Requests | C10: P0 | D10: Send friend request | E10: Button changes to Pending; request recorded | F10: Blocked | G10: Caleb | H10: 46152 | I10: , and notifications did not come in
A11: FR-02 | B11: Friend Requests | C11: P0 | D11: Recipient sees request and notification | E11: Appears in requests list and notifications | F11: Blocked | G11: Caleb | H11: 46152 | I11: , and notifications did not come in
A12: MK-01 | B12: Marketplace Listings | C12: P0 | D12: Create For Sale listing with price, images, category | E12: Published; appears in marketplace with correct data | F12: Pass | G12: Grimm | H12: 46152
A13: MK-06 | B13: Marketplace Listings | C13: P0 | D13: Try to buy your own item | E13: Blocked | F13: Pass | G13: Grimm | H13: 46152
A14: MB-01 | B14: Marketplace Buying & Escrow | C14: P0 | D14: Buyer pays successfully (Payluk) | E14: Status goes to paid; seller notified; buyer sees receipt | F14: Blocked | G14: Grimm | H14: 46152 | I14: A buyer paid for the item and it updated on the system but the seller did not get any notification at all
A15: MB-02 | B15: Marketplace Buying & Escrow | C15: P0 | D15: Payment fails or is abandoned | E15: No paid transaction created; buyer can retry | F15: Pass | G15: Grimm | H15: 46152
A16: MB-03 | B16: Marketplace Buying & Escrow | C16: P0 | D16: Double-click Buy / refresh on payment callback | E16: Only one transaction and one charge | F16: Pass | G16: Grimm | H16: 46152
A17: MB-05 | B17: Marketplace Buying & Escrow | C17: P0 | D17: Webhook: duplicate delivery, delayed delivery, bad signature | E17: Idempotent; delayed reconciles; invalid signature rejected | F17: Pass | G17: Grimm | H17: 46152
A18: MB-06 | B18: Marketplace Buying & Escrow | C18: P0 | D18: Seller marks shipped | E18: Status shipped; buyer notified | F18: Pass | G18: Grimm | H18: 46152
A19: MB-07 | B19: Marketplace Buying & Escrow | C19: P0 | D19: Buyer confirms delivery | E19: Status delivered/completed; seller balance credited once | F19: Pass | G19: Grimm | H19: 46152
A20: MB-10 | B20: Marketplace Buying & Escrow | C20: P0 | D20: Skip a state via direct API (e.g. complete before paid) | E20: Rejected by server | F20: Pass | G20: Grimm | H20: 46152
A21: WD-01 | B21: Seller Payouts & Withdrawals | C21: P0 | D21: Add payout bank account | E21: Account name resolves and is verified | F21: Pass | G21: Grimm | H21: 46152
A22: WD-02 | B22: Seller Payouts & Withdrawals | C22: P0 | D22: Enter wrong account number | E22: Rejected with clear error | F22: Pass | G22: Grimm | H22: 46152
A23: WD-03 | B23: Seller Payouts & Withdrawals | C23: P0 | D23: payout_enabled after seller setup | E23: Flips to true correctly (known issue: all false / 'Unauthorized') | F23: Pass | G23: Grimm | H23: 46152
A24: WD-04 | B24: Seller Payouts & Withdrawals | C24: P0 | D24: Balance after completed sale | E24: Pending vs available shown correctly | F24: Pass | G24: Grimm | H24: 46152
A25: WD-05 | B25: Seller Payouts & Withdrawals | C25: P0 | D25: Withdraw available balance | E25: Bank receives exact amount; status and fee correct; balance drops | F25: Blocked | G25: Grimm | H25: 46152 | I25: A seller tried to withdraw his funds but could not, the error gotten is Withdrawal failed [Payluk] POST /v1/payment/create-intent - HTTP 400 (Payluk status: 400): Minimum withdrawal amount is 1000 | body: ("status": 400,"message": "Minimum withdrawal amount is 1000" and he has 950 in his balance
A26: WD-06 | B26: Seller Payouts & Withdrawals | C26: P0 | D26: Withdraw more than balance / zero / negative / below minimum | E26: Blocked with clear message | F26: Pass | G26: Grimm | H26: 46152
A27: WD-07 | B27: Seller Payouts & Withdrawals | C27: P0 | D27: Double-click withdraw and concurrent requests | E27: Only one payout | F27: Pass | G27: Grimm | H27: 46152
A28: WD-08 | B28: Seller Payouts & Withdrawals | C28: P0 | D28: Withdrawal fails at provider | E28: Balance restored; user notified | F28: Pass | G28: Grimm | H28: 46152
A29: EV-01 | B29: Events | C29: P1 | D29: Create free event | E29: Published and discoverable | F29: Pass | G29: Grimm | H29: 46152
A30: EP-10 | B30: Event Payouts | C30: P0 | D30: View or request payout for someone else's event | E30: Denied | F30: Pass | G30: Grimm | H30: 46152
A31: NT-02 | B31: Notifications | C31: P0 | D31: Triggers: like, comment, friend request/accept, message | E31: Each fires once to the right person | F31: Pass | G31: Caleb | H31: 46152
A32: SC-01 | B32: Security | C32: P0 | D32: RLS: read or update another user's profile, chats, transactions via Supabase client | E32: Denied | F32: Pass | G32: Caleb | H32: 46152
A33: SC-02 | B33: Security | C33: P0 | D33: Tamper with price/amount in payment request | E33: Server recalculates; tampering rejected | F33: Blocked | G33: Caleb | H33: 46152 | I33: Claude to the rescue
A34: SC-04 | B34: Security | C34: P0 | D34: Escrow, payout and refund endpoints | E34: Require auth and ownership/role | F34: Blocked | G34: Caleb | H34: 46152 | I34: Claude to the rescue
A35: SC-05 | B35: Security | C35: P0 | D35: Webhook signature validation (Payluk, Paystack) | E35: Unsigned/invalid requests rejected | F35: Blocked | G35: Caleb | H35: 46152 | I35: Claude to the rescue
A36: SC-09 | B36: Security | C36: P0 | D36: Secrets in client bundle / responses | E36: None exposed | F36: Pass | G36: Caleb | H36: 46152
A37: RB-01 | B37: Responsive & Browsers | C37: P0 | D37: Every main route at 1440, 1024, 768, 375 widths | E37: No horizontal scroll, layout correct, nav works | F37: Pass | G37: Caleb | H37: 46152
A38: RB-02 | B38: Responsive & Browsers | C38: P0 | D38: Chrome, Safari (iOS), Firefox, Edge, Samsung Internet | E38: Core flows work | F38: Pass | G38: Caleb | H38: 46152
A39: PF-03 | B39: Performance & Reliability | C39: P0 | D39: Payluk slow or 502 | E39: Graceful error; no half-created transactions | F39: Pass | G39: Caleb | H39: 46244 | I39: Claude to the rescue
A40: AU-01 | B40: Auth | C40: P0 | D40: Sign up with email + password | E40: Account created; verification email (Resend) arrives within 1 min | F40: Pass | G40: victor | H40: 46183 | I40: verification email was a code
...
